2025-01-06 11:43:58 - INFO - Starting batch processing for 10 records
2025-01-06 11:43:58 - INFO - Created 10 batch tasks
2025-01-06 11:43:58 - INFO - Wrote batch tasks to JSONL file
2025-01-06 11:43:59 - INFO - HTTP Request: POST https://api.openai.com/v1/files "HTTP/1.1 200 OK"
2025-01-06 11:43:59 - INFO - Created batch file with ID: file-HVEbqZPBgD3d8jUDXix7Jh
2025-01-06 11:44:00 - INFO - HTTP Request: POST https://api.openai.com/v1/batches "HTTP/1.1 200 OK"
2025-01-06 11:44:00 - INFO - Created batch job with ID: batch_677c0850bec881908097c5428ae270be
2025-01-06 11:44:01 - INFO - HTTP Request: GET https://api.openai.com/v1/batches/batch_677c0850bec881908097c5428ae270be "HTTP/1.1 200 OK"
2025-01-06 11:44:01 - INFO - Batch job status: validating (attempt 1/3)
2025-01-06 11:45:01 - INFO - HTTP Request: GET https://api.openai.com/v1/batches/batch_677c0850bec881908097c5428ae270be "HTTP/1.1 200 OK"
2025-01-06 11:45:01 - INFO - Batch job status: completed (attempt 2/3)
2025-01-06 11:45:01 - INFO - Processing batch results
2025-01-06 11:45:01 - ERROR - Error in batch processing: Expected a non-empty value for `file_id` but received None
Traceback (most recent call last):
  File "/Users/ahmetyusufyuksek/Documents/GitHub/Sufism-and-Urban-Religiosity/scripts/batch_processing_jan.py", line 90, in process_ner_batch
    result = client.files.content(batch_job.output_file_id).content
             ^^^^^^^^^^^^^^^^^^^^^^^^^^^^^^^^^^^^^^^^^^^^^^
  File "/Users/ahmetyusufyuksek/Documents/GitHub/Sufism-and-Urban-Religiosity/venv/lib/python3.11/site-packages/openai/resources/files.py", line 288, in content
    raise ValueError(f"Expected a non-empty value for `file_id` but received {file_id!r}")
ValueError: Expected a non-empty value for `file_id` but received None
2025-01-06 11:45:01 - INFO - Cleaned up temporary files
2025-01-06 11:45:59 - INFO - Starting batch processing for 10 records
2025-01-06 11:45:59 - INFO - Created 10 batch tasks
2025-01-06 11:45:59 - INFO - Wrote batch tasks to JSONL file
2025-01-06 11:46:00 - INFO - HTTP Request: POST https://api.openai.com/v1/files "HTTP/1.1 200 OK"
2025-01-06 11:46:00 - INFO - Created batch file with ID: file-NDZVg4P49HcAvruXgaK9iJ
2025-01-06 11:46:00 - INFO - HTTP Request: POST https://api.openai.com/v1/batches "HTTP/1.1 200 OK"
2025-01-06 11:46:00 - INFO - Created batch job with ID: batch_677c08c8b4b48190af507932ef10ce22
2025-01-06 11:46:01 - INFO - HTTP Request: GET https://api.openai.com/v1/batches/batch_677c08c8b4b48190af507932ef10ce22 "HTTP/1.1 200 OK"
2025-01-06 11:46:01 - INFO - Batch job status: validating (attempt 1/3)
2025-01-06 11:47:01 - INFO - HTTP Request: GET https://api.openai.com/v1/batches/batch_677c08c8b4b48190af507932ef10ce22 "HTTP/1.1 200 OK"
2025-01-06 11:47:01 - INFO - Batch job status: completed (attempt 2/3)
2025-01-06 11:47:01 - INFO - Processing batch results
2025-01-06 11:47:01 - ERROR - Error in batch processing: Expected a non-empty value for `file_id` but received None
Traceback (most recent call last):
  File "/Users/ahmetyusufyuksek/Documents/GitHub/Sufism-and-Urban-Religiosity/scripts/batch_processing_jan.py", line 90, in process_ner_batch
    result = client.files.content(batch_job.output_file_id).content
             ^^^^^^^^^^^^^^^^^^^^^^^^^^^^^^^^^^^^^^^^^^^^^^
  File "/Users/ahmetyusufyuksek/Documents/GitHub/Sufism-and-Urban-Religiosity/venv/lib/python3.11/site-packages/openai/resources/files.py", line 288, in content
    raise ValueError(f"Expected a non-empty value for `file_id` but received {file_id!r}")
ValueError: Expected a non-empty value for `file_id` but received None
2025-01-06 11:47:01 - INFO - Cleaned up temporary files
2025-01-06 11:49:22 - INFO - Starting batch processing for 10 records
2025-01-06 11:49:22 - INFO - Created 10 batch tasks
2025-01-06 11:49:22 - INFO - Wrote batch tasks to JSONL file
2025-01-06 11:49:23 - INFO - HTTP Request: POST https://api.openai.com/v1/files "HTTP/1.1 200 OK"
2025-01-06 11:49:23 - INFO - Created batch file with ID: file-1otd1fT6oVECZdmmY7NEkJ
2025-01-06 11:49:24 - INFO - HTTP Request: POST https://api.openai.com/v1/batches "HTTP/1.1 200 OK"
2025-01-06 11:49:24 - INFO - Created batch job with ID: batch_677c099489308190921fa1d1041c5b89
2025-01-06 11:49:24 - INFO - HTTP Request: GET https://api.openai.com/v1/batches/batch_677c099489308190921fa1d1041c5b89 "HTTP/1.1 200 OK"
2025-01-06 11:49:24 - INFO - Batch job status: validating (attempt 1/3)
2025-01-06 11:50:25 - INFO - HTTP Request: GET https://api.openai.com/v1/batches/batch_677c099489308190921fa1d1041c5b89 "HTTP/1.1 200 OK"
2025-01-06 11:50:25 - INFO - Batch job status: in_progress (attempt 2/3)
2025-01-06 11:51:25 - INFO - HTTP Request: GET https://api.openai.com/v1/batches/batch_677c099489308190921fa1d1041c5b89 "HTTP/1.1 200 OK"
2025-01-06 11:51:25 - INFO - Batch job status: in_progress (attempt 3/3)
2025-01-06 11:52:25 - INFO - Processing batch results
2025-01-06 11:52:25 - ERROR - Error in batch processing: Expected a non-empty value for `file_id` but received None
Traceback (most recent call last):
  File "/Users/ahmetyusufyuksek/Documents/GitHub/Sufism-and-Urban-Religiosity/scripts/batch_processing_jan.py", line 92, in process_ner_batch
    result = client.files.content(batch_job.output_file_id).content
             ^^^^^^^^^^^^^^^^^^^^^^^^^^^^^^^^^^^^^^^^^^^^^^
  File "/Users/ahmetyusufyuksek/Documents/GitHub/Sufism-and-Urban-Religiosity/venv/lib/python3.11/site-packages/openai/resources/files.py", line 288, in content
    raise ValueError(f"Expected a non-empty value for `file_id` but received {file_id!r}")
ValueError: Expected a non-empty value for `file_id` but received None
2025-01-06 11:52:25 - INFO - Cleaned up temporary files
2025-01-06 12:09:13 - INFO - Starting batch processing test
2025-01-06 12:09:13 - INFO - Starting batch processing for 2 records
2025-01-06 12:09:14 - INFO - HTTP Request: POST https://api.openai.com/v1/files "HTTP/1.1 200 OK"
2025-01-06 12:09:15 - INFO - HTTP Request: POST https://api.openai.com/v1/batches "HTTP/1.1 200 OK"
2025-01-06 12:09:15 - INFO - HTTP Request: GET https://api.openai.com/v1/batches/batch_677c0e3b1ae08190b8e665814696aa1a "HTTP/1.1 200 OK"
2025-01-06 12:09:15 - INFO - Batch status: validating (attempt 1/60)
2025-01-06 12:10:16 - INFO - HTTP Request: GET https://api.openai.com/v1/batches/batch_677c0e3b1ae08190b8e665814696aa1a "HTTP/1.1 200 OK"
2025-01-06 12:10:16 - INFO - Batch status: in_progress (attempt 2/60)
2025-01-06 12:11:16 - INFO - HTTP Request: GET https://api.openai.com/v1/batches/batch_677c0e3b1ae08190b8e665814696aa1a "HTTP/1.1 200 OK"
2025-01-06 12:11:16 - INFO - Batch status: in_progress (attempt 3/60)
2025-01-06 12:12:16 - INFO - HTTP Request: GET https://api.openai.com/v1/batches/batch_677c0e3b1ae08190b8e665814696aa1a "HTTP/1.1 200 OK"
2025-01-06 12:12:16 - INFO - Batch status: in_progress (attempt 4/60)
2025-01-06 12:13:17 - INFO - HTTP Request: GET https://api.openai.com/v1/batches/batch_677c0e3b1ae08190b8e665814696aa1a "HTTP/1.1 200 OK"
2025-01-06 12:13:17 - INFO - Batch status: in_progress (attempt 5/60)
2025-01-06 12:14:17 - INFO - HTTP Request: GET https://api.openai.com/v1/batches/batch_677c0e3b1ae08190b8e665814696aa1a "HTTP/1.1 200 OK"
2025-01-06 12:14:17 - INFO - Batch status: in_progress (attempt 6/60)
2025-01-06 12:15:17 - INFO - HTTP Request: GET https://api.openai.com/v1/batches/batch_677c0e3b1ae08190b8e665814696aa1a "HTTP/1.1 200 OK"
2025-01-06 12:15:17 - INFO - Batch status: in_progress (attempt 7/60)
2025-01-06 12:16:17 - INFO - HTTP Request: GET https://api.openai.com/v1/batches/batch_677c0e3b1ae08190b8e665814696aa1a "HTTP/1.1 200 OK"
2025-01-06 12:16:17 - INFO - Batch status: in_progress (attempt 8/60)
2025-01-06 12:17:18 - INFO - HTTP Request: GET https://api.openai.com/v1/batches/batch_677c0e3b1ae08190b8e665814696aa1a "HTTP/1.1 200 OK"
2025-01-06 12:17:18 - INFO - Batch status: in_progress (attempt 9/60)
2025-01-06 12:18:18 - INFO - HTTP Request: GET https://api.openai.com/v1/batches/batch_677c0e3b1ae08190b8e665814696aa1a "HTTP/1.1 200 OK"
2025-01-06 12:18:18 - INFO - Batch status: in_progress (attempt 10/60)
2025-01-06 12:19:18 - INFO - HTTP Request: GET https://api.openai.com/v1/batches/batch_677c0e3b1ae08190b8e665814696aa1a "HTTP/1.1 200 OK"
2025-01-06 12:19:18 - INFO - Batch status: completed (attempt 11/60)
2025-01-06 12:20:19 - INFO - HTTP Request: GET https://api.openai.com/v1/batches/batch_677c0e3b1ae08190b8e665814696aa1a "HTTP/1.1 200 OK"
2025-01-06 12:20:19 - INFO - Batch status: completed (attempt 12/60)
2025-01-06 12:21:19 - INFO - HTTP Request: GET https://api.openai.com/v1/batches/batch_677c0e3b1ae08190b8e665814696aa1a "HTTP/1.1 200 OK"
2025-01-06 12:21:19 - INFO - Batch status: completed (attempt 13/60)
2025-01-06 12:22:20 - INFO - HTTP Request: GET https://api.openai.com/v1/batches/batch_677c0e3b1ae08190b8e665814696aa1a "HTTP/1.1 200 OK"
2025-01-06 12:22:20 - INFO - Batch status: completed (attempt 14/60)
2025-01-06 12:23:20 - INFO - HTTP Request: GET https://api.openai.com/v1/batches/batch_677c0e3b1ae08190b8e665814696aa1a "HTTP/1.1 200 OK"
2025-01-06 12:23:20 - INFO - Batch status: completed (attempt 15/60)
2025-01-06 12:23:37 - INFO - Starting batch processing test
2025-01-06 12:23:37 - ERROR - Test failed: process_ner_batch() got an unexpected keyword argument 'summary_col'
Traceback (most recent call last):
  File "/Users/ahmetyusufyuksek/Documents/GitHub/Sufism-and-Urban-Religiosity/tests/another_test.py", line 38, in test_batch_processing
    result_df = process_ner_batch(
                ^^^^^^^^^^^^^^^^^^
TypeError: process_ner_batch() got an unexpected keyword argument 'summary_col'
2025-01-06 12:23:57 - INFO - Starting batch processing for 2 records
2025-01-06 12:23:57 - INFO - Created 2 batch tasks
2025-01-06 12:23:57 - INFO - Wrote batch tasks to JSONL file
2025-01-06 12:23:58 - INFO - HTTP Request: POST https://api.openai.com/v1/files "HTTP/1.1 200 OK"
2025-01-06 12:23:58 - INFO - Created batch file with ID: file-Amp7V3N2odRjUhgoLVSZgK
2025-01-06 12:23:58 - INFO - HTTP Request: POST https://api.openai.com/v1/batches "HTTP/1.1 200 OK"
2025-01-06 12:23:58 - INFO - Created batch job with ID: batch_677c11aea5808190846a79c76a8abc29
2025-01-06 12:23:59 - INFO - HTTP Request: GET https://api.openai.com/v1/batches/batch_677c11aea5808190846a79c76a8abc29 "HTTP/1.1 200 OK"
2025-01-06 12:23:59 - INFO - Batch job status: validating (attempt 1/3)
2025-01-06 12:24:59 - INFO - HTTP Request: GET https://api.openai.com/v1/batches/batch_677c11aea5808190846a79c76a8abc29 "HTTP/1.1 200 OK"
2025-01-06 12:24:59 - INFO - Batch job status: in_progress (attempt 2/3)
2025-01-06 12:25:59 - INFO - HTTP Request: GET https://api.openai.com/v1/batches/batch_677c11aea5808190846a79c76a8abc29 "HTTP/1.1 200 OK"
2025-01-06 12:25:59 - INFO - Batch job status: completed (attempt 3/3)
2025-01-06 12:25:59 - INFO - Processing batch results
2025-01-06 12:26:00 - INFO - HTTP Request: GET https://api.openai.com/v1/files/file-FQu4srMN7qrDrqBRAsGEqs/content "HTTP/1.1 200 OK"
2025-01-06 12:26:00 - ERROR - Error processing result for Court_4_CASE_000: index 0 is out of bounds for axis 0 with size 0
2025-01-06 12:26:00 - ERROR - Error processing result for Court_5_CASE_001: index 0 is out of bounds for axis 0 with size 0
2025-01-06 12:26:00 - INFO - Batch processing completed successfully
2025-01-06 12:26:00 - INFO - Cleaned up temporary files
2025-01-06 12:33:24 - INFO - Starting batch processing for 2 records
2025-01-06 12:33:24 - INFO - Created 2 batch tasks
2025-01-06 12:33:24 - INFO - Wrote batch tasks to JSONL file
2025-01-06 12:33:25 - INFO - HTTP Request: POST https://api.openai.com/v1/files "HTTP/1.1 200 OK"
2025-01-06 12:33:25 - INFO - Created batch file with ID: file-Xts7ncRb3Fdat9aDap4VMg
2025-01-06 12:33:26 - INFO - HTTP Request: POST https://api.openai.com/v1/batches "HTTP/1.1 200 OK"
2025-01-06 12:33:26 - INFO - Created batch job with ID: batch_677c13e633308190a6f75b9b31e91c47
2025-01-06 12:33:26 - INFO - HTTP Request: GET https://api.openai.com/v1/batches/batch_677c13e633308190a6f75b9b31e91c47 "HTTP/1.1 200 OK"
2025-01-06 12:33:26 - INFO - Batch job status: validating (attempt 1/3)
2025-01-06 12:34:27 - INFO - HTTP Request: GET https://api.openai.com/v1/batches/batch_677c13e633308190a6f75b9b31e91c47 "HTTP/1.1 200 OK"
2025-01-06 12:34:27 - INFO - Batch job status: in_progress (attempt 2/3)
2025-01-06 12:35:27 - INFO - HTTP Request: GET https://api.openai.com/v1/batches/batch_677c13e633308190a6f75b9b31e91c47 "HTTP/1.1 200 OK"
2025-01-06 12:35:27 - INFO - Batch job status: completed (attempt 3/3)
2025-01-06 12:35:27 - INFO - Processing batch results
2025-01-06 12:35:28 - INFO - HTTP Request: GET https://api.openai.com/v1/files/file-1PtvdYP8gF8Jqr2Fu2s3uf/content "HTTP/1.1 200 OK"
2025-01-06 12:35:28 - ERROR - Error processing result for Court_3_CASE_000: index 0 is out of bounds for axis 0 with size 0
2025-01-06 12:35:28 - ERROR - Error processing result for Court_5_CASE_001: index 0 is out of bounds for axis 0 with size 0
2025-01-06 12:35:28 - INFO - Batch processing completed successfully
2025-01-06 12:35:28 - INFO - Cleaned up temporary files
2025-01-06 12:37:47 - INFO - Starting batch processing for 2 records
2025-01-06 12:37:47 - INFO - Created 2 batch tasks
2025-01-06 12:37:47 - INFO - Wrote batch tasks to JSONL file
2025-01-06 12:37:49 - INFO - HTTP Request: POST https://api.openai.com/v1/files "HTTP/1.1 200 OK"
2025-01-06 12:37:49 - INFO - Created batch file with ID: file-FoDyrScQQokCSXw19nxTHq
2025-01-06 12:37:50 - INFO - HTTP Request: POST https://api.openai.com/v1/batches "HTTP/1.1 200 OK"
2025-01-06 12:37:50 - INFO - Created batch job with ID: batch_677c14edcb9c8190b993e30c07270c38
2025-01-06 12:37:50 - INFO - HTTP Request: GET https://api.openai.com/v1/batches/batch_677c14edcb9c8190b993e30c07270c38 "HTTP/1.1 200 OK"
2025-01-06 12:37:50 - INFO - Batch job status: validating (attempt 1/3)
2025-01-06 12:38:50 - INFO - HTTP Request: GET https://api.openai.com/v1/batches/batch_677c14edcb9c8190b993e30c07270c38 "HTTP/1.1 200 OK"
2025-01-06 12:38:50 - INFO - Batch job status: completed (attempt 2/3)
2025-01-06 12:38:50 - INFO - Processing batch results
2025-01-06 12:38:51 - INFO - HTTP Request: GET https://api.openai.com/v1/files/file-YEfWbVJnk4nB5b1979eHFo/content "HTTP/1.1 200 OK"
2025-01-06 12:38:51 - ERROR - No matching case_id found: 3_CASE_000
2025-01-06 12:38:51 - ERROR - No matching case_id found: 2_CASE_001
2025-01-06 12:38:51 - INFO - Batch processing completed successfully
2025-01-06 12:38:51 - INFO - Cleaned up temporary files
2025-01-06 12:45:58 - INFO - Starting batch processing for 2 records
2025-01-06 12:45:58 - INFO - Created 2 batch tasks
2025-01-06 12:45:58 - INFO - Wrote batch tasks to JSONL file
2025-01-06 12:45:58 - INFO - HTTP Request: POST https://api.openai.com/v1/files "HTTP/1.1 200 OK"
2025-01-06 12:45:58 - INFO - Created batch file with ID: file-TNqwYtAhhgmQTQcAigXBmy
2025-01-06 12:46:00 - INFO - HTTP Request: POST https://api.openai.com/v1/batches "HTTP/1.1 200 OK"
2025-01-06 12:46:00 - INFO - Created batch job with ID: batch_677c16d7c0f48190b7d23daad952afaf
2025-01-06 12:46:00 - INFO - HTTP Request: GET https://api.openai.com/v1/batches/batch_677c16d7c0f48190b7d23daad952afaf "HTTP/1.1 200 OK"
2025-01-06 12:46:00 - INFO - Batch job status: validating (attempt 1/3)
2025-01-06 12:47:00 - INFO - HTTP Request: GET https://api.openai.com/v1/batches/batch_677c16d7c0f48190b7d23daad952afaf "HTTP/1.1 200 OK"
2025-01-06 12:47:00 - INFO - Batch job status: completed (attempt 2/3)
2025-01-06 12:47:00 - INFO - Processing batch results
2025-01-06 12:47:01 - INFO - HTTP Request: GET https://api.openai.com/v1/files/file-EomGDzKbL9zqNrMUsZsAcF/content "HTTP/1.1 200 OK"
2025-01-06 12:47:01 - ERROR - No matching case_id found: 3_Court_3_001_000
2025-01-06 12:47:01 - ERROR - No matching case_id found: 1_Court_1_001_001
2025-01-06 12:47:01 - INFO - Batch processing completed successfully
2025-01-06 12:47:01 - INFO - Cleaned up temporary files
2025-01-06 13:06:10 - INFO - Starting batch processing for 2 records
2025-01-06 13:06:10 - INFO - Created 2 batch tasks
2025-01-06 13:06:10 - INFO - Wrote batch tasks to JSONL file
2025-01-06 13:06:11 - INFO - HTTP Request: POST https://api.openai.com/v1/files "HTTP/1.1 200 OK"
2025-01-06 13:06:11 - INFO - Created batch file with ID: file-Sy9488Ny5EVgenodkSHcTQ
2025-01-06 13:06:13 - INFO - HTTP Request: POST https://api.openai.com/v1/batches "HTTP/1.1 200 OK"
2025-01-06 13:06:13 - INFO - Created batch job with ID: batch_677c1b94c2f0819086b53bfbd6f1f07c
2025-01-06 13:06:13 - INFO - HTTP Request: GET https://api.openai.com/v1/batches/batch_677c1b94c2f0819086b53bfbd6f1f07c "HTTP/1.1 200 OK"
2025-01-06 13:06:13 - INFO - Batch job status: validating (attempt 1/3)
2025-01-06 13:07:13 - INFO - HTTP Request: GET https://api.openai.com/v1/batches/batch_677c1b94c2f0819086b53bfbd6f1f07c "HTTP/1.1 200 OK"
2025-01-06 13:07:13 - INFO - Batch job status: in_progress (attempt 2/3)
2025-01-06 13:08:14 - INFO - HTTP Request: GET https://api.openai.com/v1/batches/batch_677c1b94c2f0819086b53bfbd6f1f07c "HTTP/1.1 200 OK"
2025-01-06 13:08:14 - INFO - Batch job status: in_progress (attempt 3/3)
2025-01-06 13:09:14 - INFO - Processing batch results
2025-01-06 13:09:14 - ERROR - Error in batch processing: Expected a non-empty value for `file_id` but received None
Traceback (most recent call last):
  File "/Users/ahmetyusufyuksek/Documents/GitHub/Sufism-and-Urban-Religiosity/scripts/batch_processing_jan.py", line 99, in process_ner_batch
    result = client.files.content(batch_job.output_file_id).content
             ^^^^^^^^^^^^^^^^^^^^^^^^^^^^^^^^^^^^^^^^^^^^^^
  File "/Users/ahmetyusufyuksek/Documents/GitHub/Sufism-and-Urban-Religiosity/venv/lib/python3.11/site-packages/openai/resources/files.py", line 288, in content
    raise ValueError(f"Expected a non-empty value for `file_id` but received {file_id!r}")
ValueError: Expected a non-empty value for `file_id` but received None
2025-01-06 13:09:14 - INFO - Cleaned up temporary files
2025-01-06 18:04:02 - INFO - Starting batch processing for 2 records
2025-01-06 18:04:02 - INFO - Created 2 batch tasks
2025-01-06 18:04:02 - INFO - Wrote batch tasks to JSONL file
2025-01-06 18:04:03 - INFO - HTTP Request: POST https://api.openai.com/v1/files "HTTP/1.1 200 OK"
2025-01-06 18:04:03 - INFO - Created batch file with ID: file-VDjKrECU6wTN4GN9Cx24xb
2025-01-06 18:04:04 - INFO - HTTP Request: POST https://api.openai.com/v1/batches "HTTP/1.1 200 OK"
2025-01-06 18:04:04 - INFO - Created batch job with ID: batch_677c6164aab08190bb90a7c38b1c8fbb
2025-01-06 18:04:05 - INFO - HTTP Request: GET https://api.openai.com/v1/batches/batch_677c6164aab08190bb90a7c38b1c8fbb "HTTP/1.1 200 OK"
2025-01-06 18:04:05 - INFO - Batch job status: validating (attempt 1/3)
2025-01-06 18:05:05 - INFO - HTTP Request: GET https://api.openai.com/v1/batches/batch_677c6164aab08190bb90a7c38b1c8fbb "HTTP/1.1 200 OK"
2025-01-06 18:05:05 - INFO - Batch job status: completed (attempt 2/3)
2025-01-06 18:05:06 - INFO - HTTP Request: GET https://api.openai.com/v1/files/file-Q1B5WdwxFZGRnrKJQccTch/content "HTTP/1.1 200 OK"
2025-01-06 18:05:06 - INFO - Batch results saved to batch_results.jsonl
2025-01-06 18:05:06 - INFO - Processing batch results
2025-01-06 18:05:06 - ERROR - No matching case_id found: 4_Court_4_000
2025-01-06 18:05:06 - ERROR - No matching case_id found: 4_Court_4_001
2025-01-06 18:05:06 - INFO - Batch processing completed successfully
2025-01-06 18:05:06 - INFO - Cleaned up temporary files
2025-01-06 18:22:42 - INFO - Starting batch processing for 2 records
2025-01-06 18:22:42 - ERROR - Error in batch processing: 'court'
Traceback (most recent call last):
  File "/Users/ahmetyusufyuksek/Documents/GitHub/Sufism-and-Urban-Religiosity/venv/lib/python3.11/site-packages/pandas/core/indexes/base.py", line 3805, in get_loc
    return self._engine.get_loc(casted_key)
           ^^^^^^^^^^^^^^^^^^^^^^^^^^^^^^^^
  File "index.pyx", line 167, in pandas._libs.index.IndexEngine.get_loc
  File "index.pyx", line 196, in pandas._libs.index.IndexEngine.get_loc
  File "pandas/_libs/hashtable_class_helper.pxi", line 7081, in pandas._libs.hashtable.PyObjectHashTable.get_item
  File "pandas/_libs/hashtable_class_helper.pxi", line 7089, in pandas._libs.hashtable.PyObjectHashTable.get_item
KeyError: 'court'

The above exception was the direct cause of the following exception:

Traceback (most recent call last):
  File "/Users/ahmetyusufyuksek/Documents/GitHub/Sufism-and-Urban-Religiosity/scripts/batch_processing_jan.py", line 41, in process_ner_batch
    "custom_id": f"{row[court_title_column_name]}_{row[case_id_column_name]}",
                    ~~~^^^^^^^^^^^^^^^^^^^^^^^^^
  File "/Users/ahmetyusufyuksek/Documents/GitHub/Sufism-and-Urban-Religiosity/venv/lib/python3.11/site-packages/pandas/core/series.py", line 1121, in __getitem__
    return self._get_value(key)
           ^^^^^^^^^^^^^^^^^^^^
  File "/Users/ahmetyusufyuksek/Documents/GitHub/Sufism-and-Urban-Religiosity/venv/lib/python3.11/site-packages/pandas/core/series.py", line 1237, in _get_value
    loc = self.index.get_loc(label)
          ^^^^^^^^^^^^^^^^^^^^^^^^^
  File "/Users/ahmetyusufyuksek/Documents/GitHub/Sufism-and-Urban-Religiosity/venv/lib/python3.11/site-packages/pandas/core/indexes/base.py", line 3812, in get_loc
    raise KeyError(key) from err
KeyError: 'court'
2025-01-06 18:23:53 - INFO - Starting batch processing for 2 records
2025-01-06 18:23:53 - ERROR - Error in batch processing: 'court'
Traceback (most recent call last):
  File "/Users/ahmetyusufyuksek/Documents/GitHub/Sufism-and-Urban-Religiosity/venv/lib/python3.11/site-packages/pandas/core/indexes/base.py", line 3805, in get_loc
    return self._engine.get_loc(casted_key)
           ^^^^^^^^^^^^^^^^^^^^^^^^^^^^^^^^
  File "index.pyx", line 167, in pandas._libs.index.IndexEngine.get_loc
  File "index.pyx", line 196, in pandas._libs.index.IndexEngine.get_loc
  File "pandas/_libs/hashtable_class_helper.pxi", line 7081, in pandas._libs.hashtable.PyObjectHashTable.get_item
  File "pandas/_libs/hashtable_class_helper.pxi", line 7089, in pandas._libs.hashtable.PyObjectHashTable.get_item
KeyError: 'court'

The above exception was the direct cause of the following exception:

Traceback (most recent call last):
  File "/Users/ahmetyusufyuksek/Documents/GitHub/Sufism-and-Urban-Religiosity/scripts/batch_processing_jan.py", line 41, in process_ner_batch
    "custom_id": f"{row[court_title_column_name]}_{row[case_id_column_name]}",
                    ~~~^^^^^^^^^^^^^^^^^^^^^^^^^
  File "/Users/ahmetyusufyuksek/Documents/GitHub/Sufism-and-Urban-Religiosity/venv/lib/python3.11/site-packages/pandas/core/series.py", line 1121, in __getitem__
    return self._get_value(key)
           ^^^^^^^^^^^^^^^^^^^^
  File "/Users/ahmetyusufyuksek/Documents/GitHub/Sufism-and-Urban-Religiosity/venv/lib/python3.11/site-packages/pandas/core/series.py", line 1237, in _get_value
    loc = self.index.get_loc(label)
          ^^^^^^^^^^^^^^^^^^^^^^^^^
  File "/Users/ahmetyusufyuksek/Documents/GitHub/Sufism-and-Urban-Religiosity/venv/lib/python3.11/site-packages/pandas/core/indexes/base.py", line 3812, in get_loc
    raise KeyError(key) from err
KeyError: 'court'
2025-01-06 18:27:39 - INFO - Starting batch processing for 2 records
2025-01-06 18:27:39 - ERROR - Error in batch processing: 'court'
Traceback (most recent call last):
  File "/Users/ahmetyusufyuksek/Documents/GitHub/Sufism-and-Urban-Religiosity/venv/lib/python3.11/site-packages/pandas/core/indexes/base.py", line 3805, in get_loc
    return self._engine.get_loc(casted_key)
           ^^^^^^^^^^^^^^^^^^^^^^^^^^^^^^^^
  File "index.pyx", line 167, in pandas._libs.index.IndexEngine.get_loc
  File "index.pyx", line 196, in pandas._libs.index.IndexEngine.get_loc
  File "pandas/_libs/hashtable_class_helper.pxi", line 7081, in pandas._libs.hashtable.PyObjectHashTable.get_item
  File "pandas/_libs/hashtable_class_helper.pxi", line 7089, in pandas._libs.hashtable.PyObjectHashTable.get_item
KeyError: 'court'

The above exception was the direct cause of the following exception:

Traceback (most recent call last):
  File "/Users/ahmetyusufyuksek/Documents/GitHub/Sufism-and-Urban-Religiosity/scripts/batch_processing_jan.py", line 41, in process_ner_batch
    "custom_id": f"{row[court_title_column_name]}_{row[case_id_column_name]}",
                    ~~~^^^^^^^^^^^^^^^^^^^^^^^^^
  File "/Users/ahmetyusufyuksek/Documents/GitHub/Sufism-and-Urban-Religiosity/venv/lib/python3.11/site-packages/pandas/core/series.py", line 1121, in __getitem__
    return self._get_value(key)
           ^^^^^^^^^^^^^^^^^^^^
  File "/Users/ahmetyusufyuksek/Documents/GitHub/Sufism-and-Urban-Religiosity/venv/lib/python3.11/site-packages/pandas/core/series.py", line 1237, in _get_value
    loc = self.index.get_loc(label)
          ^^^^^^^^^^^^^^^^^^^^^^^^^
  File "/Users/ahmetyusufyuksek/Documents/GitHub/Sufism-and-Urban-Religiosity/venv/lib/python3.11/site-packages/pandas/core/indexes/base.py", line 3812, in get_loc
    raise KeyError(key) from err
KeyError: 'court'
2025-01-06 18:28:18 - INFO - Starting batch processing for 2 records
2025-01-06 18:28:18 - ERROR - Error in batch processing: 'court'
Traceback (most recent call last):
  File "/Users/ahmetyusufyuksek/Documents/GitHub/Sufism-and-Urban-Religiosity/venv/lib/python3.11/site-packages/pandas/core/indexes/base.py", line 3805, in get_loc
    return self._engine.get_loc(casted_key)
           ^^^^^^^^^^^^^^^^^^^^^^^^^^^^^^^^
  File "index.pyx", line 167, in pandas._libs.index.IndexEngine.get_loc
  File "index.pyx", line 196, in pandas._libs.index.IndexEngine.get_loc
  File "pandas/_libs/hashtable_class_helper.pxi", line 7081, in pandas._libs.hashtable.PyObjectHashTable.get_item
  File "pandas/_libs/hashtable_class_helper.pxi", line 7089, in pandas._libs.hashtable.PyObjectHashTable.get_item
KeyError: 'court'

The above exception was the direct cause of the following exception:

Traceback (most recent call last):
  File "/Users/ahmetyusufyuksek/Documents/GitHub/Sufism-and-Urban-Religiosity/scripts/batch_processing_jan.py", line 41, in process_ner_batch
    "custom_id": f"{row[court_title_column_name]}_{row[case_id_column_name]}",
                    ~~~^^^^^^^^^^^^^^^^^^^^^^^^^
  File "/Users/ahmetyusufyuksek/Documents/GitHub/Sufism-and-Urban-Religiosity/venv/lib/python3.11/site-packages/pandas/core/series.py", line 1121, in __getitem__
    return self._get_value(key)
           ^^^^^^^^^^^^^^^^^^^^
  File "/Users/ahmetyusufyuksek/Documents/GitHub/Sufism-and-Urban-Religiosity/venv/lib/python3.11/site-packages/pandas/core/series.py", line 1237, in _get_value
    loc = self.index.get_loc(label)
          ^^^^^^^^^^^^^^^^^^^^^^^^^
  File "/Users/ahmetyusufyuksek/Documents/GitHub/Sufism-and-Urban-Religiosity/venv/lib/python3.11/site-packages/pandas/core/indexes/base.py", line 3812, in get_loc
    raise KeyError(key) from err
KeyError: 'court'
2025-01-06 18:35:46 - INFO - Starting batch processing for 2 records
2025-01-06 18:35:46 - INFO - Created 2 batch tasks
2025-01-06 18:35:46 - INFO - Wrote batch tasks to JSONL file
2025-01-06 18:35:47 - INFO - HTTP Request: POST https://api.openai.com/v1/files "HTTP/1.1 200 OK"
2025-01-06 18:35:47 - INFO - Created batch file with ID: file-GKSX5HGV1ga9jihGk3RME1
2025-01-06 18:35:48 - INFO - HTTP Request: POST https://api.openai.com/v1/batches "HTTP/1.1 200 OK"
2025-01-06 18:35:48 - INFO - Created batch job with ID: batch_677c68d3e9f081908cf279c53019a12d
2025-01-06 18:35:48 - INFO - HTTP Request: GET https://api.openai.com/v1/batches/batch_677c68d3e9f081908cf279c53019a12d "HTTP/1.1 200 OK"
2025-01-06 18:35:48 - INFO - Batch job status: validating (attempt 1/3)
2025-01-06 18:36:48 - INFO - HTTP Request: GET https://api.openai.com/v1/batches/batch_677c68d3e9f081908cf279c53019a12d "HTTP/1.1 200 OK"
2025-01-06 18:36:48 - INFO - Batch job status: completed (attempt 2/3)
2025-01-06 18:36:49 - INFO - HTTP Request: GET https://api.openai.com/v1/files/file-EfN8ZXuMiZwWJsz7GHihBo/content "HTTP/1.1 200 OK"
2025-01-06 18:36:49 - INFO - Batch results saved to batch_results.jsonl
2025-01-06 18:36:49 - INFO - Processing batch results
2025-01-06 18:36:49 - INFO - HTTP Request: GET https://api.openai.com/v1/files/file-EfN8ZXuMiZwWJsz7GHihBo/content "HTTP/1.1 200 OK"
2025-01-06 18:36:49 - INFO - Batch processing completed successfully
2025-01-06 18:36:49 - INFO - Cleaned up temporary files
2025-01-06 18:36:49 - INFO - Test passed: Batch processing completed successfully.
2025-01-06 18:36:49 - INFO - Cleaned up test output file.
2025-01-06 18:42:58 - INFO - Starting batch processing for 2 records
2025-01-06 18:42:58 - INFO - Created 2 batch tasks
2025-01-06 18:42:58 - INFO - Wrote batch tasks to JSONL file
2025-01-06 18:42:59 - INFO - HTTP Request: POST https://api.openai.com/v1/files "HTTP/1.1 200 OK"
2025-01-06 18:42:59 - INFO - Created batch file with ID: file-HTSjj4Z96hd3bYxz2BvqAJ
2025-01-06 18:43:00 - INFO - HTTP Request: POST https://api.openai.com/v1/batches "HTTP/1.1 200 OK"
2025-01-06 18:43:00 - INFO - Created batch job with ID: batch_677c6a8440708190b38899b5fa76f80b
2025-01-06 18:43:01 - INFO - HTTP Request: GET https://api.openai.com/v1/batches/batch_677c6a8440708190b38899b5fa76f80b "HTTP/1.1 200 OK"
2025-01-06 18:43:01 - INFO - Batch job status: validating (attempt 1/3)
2025-01-06 18:44:01 - INFO - HTTP Request: GET https://api.openai.com/v1/batches/batch_677c6a8440708190b38899b5fa76f80b "HTTP/1.1 200 OK"
2025-01-06 18:44:01 - INFO - Batch job status: in_progress (attempt 2/3)
2025-01-06 18:45:01 - INFO - HTTP Request: GET https://api.openai.com/v1/batches/batch_677c6a8440708190b38899b5fa76f80b "HTTP/1.1 200 OK"
2025-01-06 18:45:01 - INFO - Batch job status: completed (attempt 3/3)
2025-01-06 18:45:02 - INFO - HTTP Request: GET https://api.openai.com/v1/files/file-J9xkPDc51pGosuiPf2CV4A/content "HTTP/1.1 200 OK"
2025-01-06 18:45:02 - INFO - Batch results saved to batch_results.jsonl
2025-01-06 18:45:02 - INFO - Processing batch results
2025-01-06 18:45:03 - INFO - HTTP Request: GET https://api.openai.com/v1/files/file-J9xkPDc51pGosuiPf2CV4A/content "HTTP/1.1 200 OK"
2025-01-06 18:45:03 - INFO - Batch processing completed successfully
2025-01-06 18:45:03 - INFO - Cleaned up temporary files
2025-01-06 18:45:03 - INFO - Test passed: Batch processing completed successfully.
